Workbook

Sheet assumptions
A1: MFR Analytics
A2: Financial Planning & Analysis Model
A3: 2024-2026
A6: Revenue Assumptions | B6: 2024 | C6: 2025 | D6: 2026
A7: Subscription Revenue | B7: 36000000 | C7: 41400000 | D7: =C7*(1+D10) -> 47610000
A8: Professional Services Revenue | B8: 4000000 | C8: =B8*(1+B10) -> 4600000 | D8: =C8*(1+D10) -> 5290000
A9: Total Revenue | B9: =SUM(B7:B8) -> 40000000 | C9: =SUM(C7:C8) -> 46000000 | D9: =SUM(D7:D8) -> 52900000
A10: Revenue Growth | B10: 0.15 | C10: 0.15 | D10: 0.15
A13: Department | B13: 2024 Headcount | C13: 2025 Headcount | D13: Proposed 2026 Headcount
A14: Engineering | B14: 70 | C14: 76 | D14: 82
A15: Sales | B15: 50 | C15: 55 | D15: 60
A16: Customer Success | B16: 30 | C16: 33 | D16: 36
A17: Marketing | B17: 20 | C17: 22 | D17: 24
A18: Product | B18: 15 | C18: 17 | D18: 19
A19: G&A | B19: 25 | C19: 26 | D19: 27
A20: Total | B20: =SUM(B14:B19) -> 210 | C20: =SUM(C14:C19) -> 229 | D20: =SUM(D14:D19) -> 248
A23: Department | B23: 2024 Avg. Salary | C23: 2025 Avg. Salary | D23: 2026 Avg. Salary
A24: Engineering | B24: 135000 | C24: =B24*(1+$B$34) -> 139050 | D24: =C24*(1+$C$34) -> 143221.5
A25: Sales | B25: 100000 | C25: =B25*(1+$B$34) -> 103000 | D25: =C25*(1+$C$34) -> 106090
A26: Customer Success | B26: 85000 | C26: =B26*(1+$B$34) -> 87550 | D26: =C26*(1+$C$34) -> 90176.5
A27: Marketing | B27: 95000 | C27: =B27*(1+$B$34) -> 97850 | D27: =C27*(1+$C$34) -> 100785.5
A28: Product | B28: 125000 | C28: =B28*(1+$B$34) -> 128750 | D28: =C28*(1+$C$34) -> 132612.5
A29: G&A | B29: 105000 | C29: =B29*(1+$B$34) -> 108150 | D29: =C29*(1+$C$34) -> 111394.5
A32: Assumption | B32: 2024 Value | C32: 2025 Value | D32: 2026 Value
A33: Benefits as % of Salary | B33: 0.2 | C33: 0.2 | D33: 0.2
A34: Annual Salary Increase | B34: 0.03 | C34: 0.03 | D34: 0.03
A35: Subscription Revenue % | B35: 0.9 | C35: 0.9 | D35: 0.9
A36: Professional Services Revenue % | B36: 0.1 | C36: 0.1 | D36: 0.1
A39: Operating Expense Assumptions | B39: 2024 | C39: 2025 | D39: 2026
A40: Sales Commission % of Subscription Revenue | B40: 0.05 | C40: 0.05 | D40: 0.05
A41: Software Cost per Employee | B41: 3000 | C41: 3000 | D41: 3000
A42: Sales Travel per Employee | B42: 4000 | C42: 4000 | D42: 4000
A43: Customer Success Travel Per Employee | B43: 2000 | C43: 2000 | D43: 2000
A44: Marketing Travel per Employee | B44: 2500 | C44: 2500 | D44: 2500
A45: Marketing & Advertising % of Revenue | B45: 0.06 | C45: 0.06 | D45: 0.06
A46: Engineering Cloud & Hosting % of Revenue | B46: 0.04 | C46: 0.04 | D46: 0.04
... A49: Rent & Facilities per Employee | B49: 6000 | C49: 6000 | D49: 6000
A52: Monthly Revenue Allocation | B52: Jan | C52: Feb | D52: Mar | E52: Apr | F52: May | G52: Jun | H52: Jul | I52: Aug | J52: Sep | K52: Oct | L52: Nov | M52: Dec | N52: Total
A53: % of Annual Revenue 2024 | B53: 0.07 | C53: 0.07 | D53: 0.08 | E53: 0.08 | F53: 0.08 | G53: 0.08 | H53: 0.08 | I53: 0.08 | J53: 0.09 | K53: 0.09 | L53: 0.09 | M53: 0.11 | N53: =SUM(B53:M53) -> 1
A54: % of Annual Revenue 2025 | B54: 0.07 | C54: 0.07 | D54: 0.08 | E54: 0.08 | F54: 0.08 | G54: 0.08 | H54: 0.08 | I54: 0.08 | J54: 0.09 | K54: 0.09 | L54: 0.09 | M54: 0.11 | N54: =SUM(B54:M54) -> 1

Sheet 2024_budget
A1: Revenue | B1: Jan | C1: Feb | D1: Mar | E1: Apr | F1: May | G1: Jun | H1: Jul | I1: Aug | J1: Sep | K1: Oct | L1: Nov | M1: Dec | N1: FY 2024
A2: Subscription Revenue | B2: =assumptions!$B$7*assumptions!B53 -> 2520000 | C2: =assumptions!$B$7*assumptions!C53 -> 2520000 | D2: =assumptions!$B$7*assumptions!D53 -> 2880000 | E2: =assumptions!$B$7*assumptions!E53 -> 2880000 | F2: =assumptions!$B$7*assumptions!F53 -> 2880000 | G2: =assumptions!$B$7*assumptions!G53 -> 2880000 | H2: =assumptions!$B$7*assumptions!H53 -> 2880000 | I2: =assumptions!$B$7*assumptions!I53 -> 2880000 | ... M2: =assumptions!$B$7*assumptions!M53 -> 3960000 | N2: =SUM(B2:M2) -> 36000000
A3: Professional Services | B3: =assumptions!$B$8*assumptions!B53 -> 280000 | C3: =assumptions!$B$8*assumptions!C53 -> 280000 | D3: =assumptions!$B$8*assumptions!D53 -> 320000 | E3: =assumptions!$B$8*assumptions!E53 -> 320000 | F3: =assumptions!$B$8*assumptions!F53 -> 320000 | G3: =assumptions!$B$8*assumptions!G53 -> 320000 | H3: =assumptions!$B$8*assumptions!H53 -> 320000 | I3: =assumptions!$B$8*assumptions!I53 -> 320000 | ... M3: =assumptions!$B$8*assumptions!M53 -> 440000 | N3: =SUM(B3:M3) -> 4000000
A4: Total Revenue | B4: =SUM(B2:B3) -> 2800000 | C4: =SUM(C2:C3) -> 2800000 | D4: =SUM(D2:D3) -> 3200000 | E4: =SUM(E2:E3) -> 3200000 | F4: =SUM(F2:F3) -> 3200000 | G4: =SUM(G2:G3) -> 3200000 | H4: =SUM(H2:H3) -> 3200000 | I4: =SUM(I2:I3) -> 3200000 | ... N4: =SUM(N2:N3) -> 40000000
A7: Sales | B7: Jan | C7: Feb | D7: Mar | E7: Apr | F7: May | G7: Jun | H7: Jul | I7: Aug | J7: Sep | K7: Oct | L7: Nov | M7: Dec | N7: FY 2024
A8: Salaries & Wages | B8: =assumptions!$B$15*assumptions!$B$25/12 -> 416666.67 | C8: =assumptions!$B$15*assumptions!$B$25/12 -> 416666.67 | D8: =assumptions!$B$15*assumptions!$B$25/12 -> 416666.67 | E8: =assumptions!$B$15*assumptions!$B$25/12 -> 416666.67 | F8: =assumptions!$B$15*assumptions!$B$25/12 -> 416666.67 | G8: =assumptions!$B$15*assumptions!$B$25/12 -> 416666.67 | H8: =assumptions!$B$15*assumptions!$B$25/12 -> 416666.67 | I8: =assumptions!$B$15*assumptions!$B$25/12 -> 416666.67 | ... M8: =assumptions!$B$15*assumptions!$B$25/12 -> 416666.67 | N8: =SUM(B8:M8) -> 5000000
A9: Employee Benefits | B9: =$B$8*assumptions!$B$33 -> 83333.333 | C9: =$B$8*assumptions!$B$33 -> 83333.333 | D9: =$B$8*assumptions!$B$33 -> 83333.333 | E9: =$B$8*assumptions!$B$33 -> 83333.333 | F9: =$B$8*assumptions!$B$33 -> 83333.333 | G9: =$B$8*assumptions!$B$33 -> 83333.333 | H9: =$B$8*assumptions!$B$33 -> 83333.333 | I9: =$B$8*assumptions!$B$33 -> 83333.333 | ... M9: =$B$8*assumptions!$B$33 -> 83333.333 | N9: =SUM(B9:M9) -> 1000000
A10: Sales Commissions | B10: =B2*assumptions!$B$40 -> 126000 | C10: =C2*assumptions!$B$40 -> 126000 | D10: =D2*assumptions!$B$40 -> 144000 | E10: =E2*assumptions!$B$40 -> 144000 | F10: =F2*assumptions!$B$40 -> 144000 | G10: =G2*assumptions!$B$40 -> 144000 | H10: =H2*assumptions!$B$40 -> 144000 | I10: =I2*assumptions!$B$40 -> 144000 | ... M10: =M2*assumptions!$B$40 -> 198000 | N10: =SUM(B10:M10) -> 1800000
A11: Software & Tools | B11: =(assumptions!$B$15*assumptions!$B$41)/12 -> 12500 | C11: =(assumptions!$B$15*assumptions!$B$41)/12 -> 12500 | D11: =(assumptions!$B$15*assumptions!$B$41)/12 -> 12500 | E11: =(assumptions!$B$15*assumptions!$B$41)/12 -> 12500 | F11: =(assumptions!$B$15*assumptions!$B$41)/12 -> 12500 | G11: =(assumptions!$B$15*assumptions!$B$41)/12 -> 12500 | H11: =(assumptions!$B$15*assumptions!$B$41)/12 -> 12500 | I11: =(assumptions!$B$15*assumptions!$B$41)/12 -> 12500 | ... M11: =(assumptions!$B$15*assumptions!$B$41)/12 -> 12500 | N11: =SUM(B11:M11) -> 150000
A12: Travel & Entertainment | B12: =(assumptions!$B$15*assumptions!$B$42)/12 -> 16666.667 | C12: =(assumptions!$B$15*assumptions!$B$42)/12 -> 16666.667 | D12: =(assumptions!$B$15*assumptions!$B$42)/12 -> 16666.667 | E12: =(assumptions!$B$15*assumptions!$B$42)/12 -> 16666.667 | F12: =(assumptions!$B$15*assumptions!$B$42)/12 -> 16666.667 | G12: =(assumptions!$B$15*assumptions!$B$42)/12 -> 16666.667 | H12: =(assumptions!$B$15*assumptions!$B$42)/12 -> 16666.667 | I12: =(assumptions!$B$15*assumptions!$B$42)/12 -> 16666.667 | ... M12: =(assumptions!$B$15*assumptions!$B$42)/12 -> 16666.667 | N12: =SUM(B12:M12) -> 200000
A13: Total Sales Expenses | B13: =SUM(B8:B12) -> 655166.67 | C13: =SUM(C8:C12) -> 655166.67 | D13: =SUM(D8:D12) -> 673166.67 | E13: =SUM(E8:E12) -> 673166.67 | F13: =SUM(F8:F12) -> 673166.67 | G13: =SUM(G8:G12) -> 673166.67 | H13: =SUM(H8:H12) -> 673166.67 | I13: =SUM(I8:I12) -> 673166.67 | ... N13: =SUM(N8:N12) -> 8150000
A16: Marketing | B16: Jan | C16: Feb | D16: Mar | E16: Apr | F16: May | G16: Jun | H16: Jul | I16: Aug | J16: Sep | K16: Oct | L16: Nov | M16: Dec | N16: FY 2024
A17: Salaries & Wages | B17: =(assumptions!$B$27*assumptions!$B$17)/12 -> 158333.33 | C17: =(assumptions!$B$27*assumptions!$B$17)/12 -> 158333.33 | D17: =(assumptions!$B$27*assumptions!$B$17)/12 -> 158333.33 | E17: =(assumptions!$B$27*assumptions!$B$17)/12 -> 158333.33 | F17: =(assumptions!$B$27*assumptions!$B$17)/12 -> 158333.33 | G17: =(assumptions!$B$27*assumptions!$B$17)/12 -> 158333.33 | H17: =(assumptions!$B$27*assumptions!$B$17)/12 -> 158333.33 | I17: =(assumptions!$B$27*assumptions!$B$17)/12 -> 158333.33 | ... M17: =(assumptions!$B$27*assumptions!$B$17)/12 -> 158333.33 | N17: =SUM(B17:M17) -> 1900000
A18: Employee Benefits | B18: =B17*assumptions!$B$33 -> 31666.667 | C18: =C17*assumptions!$B$33 -> 31666.667 | D18: =D17*assumptions!$B$33 -> 31666.667 | E18: =E17*assumptions!$B$33 -> 31666.667 | F18: =F17*assumptions!$B$33 -> 31666.667 | G18: =G17*assumptions!$B$33 -> 31666.667 | H18: =H17*assumptions!$B$33 -> 31666.667 | I18: =I17*assumptions!$B$33 -> 31666.667 | ... M18: =M17*assumptions!$B$33 -> 31666.667 | N18: =SUM(B18:M18) -> 380000
A19: Marketing & Advertising | B19: =B4*assumptions!$B$45 -> 168000 | C19: =C4*assumptions!$B$45 -> 168000 | D19: =D4*assumptions!$B$45 -> 192000 | E19: =E4*assumptions!$B$45 -> 192000 | F19: =F4*assumptions!$B$45 -> 192000 | G19: =G4*assumptions!$B$45 -> 192000 | H19: =H4*assumptions!$B$45 -> 192000 | I19: =I4*assumptions!$B$45 -> 192000 | ... M19: =M4*assumptions!$B$45 -> 264000 | N19: =SUM(B19:M19) -> 2400000
A20: Software & Tools | B20: =(assumptions!$B$17*assumptions!$B$41)/12 -> 5000 | C20: =(assumptions!$B$17*assumptions!$B$41)/12 -> 5000 | D20: =(assumptions!$B$17*assumptions!$B$41)/12 -> 5000 | E20: =(assumptions!$B$17*assumptions!$B$41)/12 -> 5000 | F20: =(assumptions!$B$17*assumptions!$B$41)/12 -> 5000 | G20: =(assumptions!$B$17*assumptions!$B$41)/12 -> 5000 | H20: =(assumptions!$B$17*assumptions!$B$41)/12 -> 5000 | I20: =(assumptions!$B$17*assumptions!$B$41)/12 -> 5000 | ... M20: =(assumptions!$B$17*assumptions!$B$41)/12 -> 5000 | N20: =SUM(B20:M20) -> 60000
A21: Travel & Entertainment | B21: =(assumptions!$B$44*assumptions!$B$17)/12 -> 4166.6667 | C21: =(assumptions!$B$44*assumptions!$B$17)/12 -> 4166.6667 | D21: =(assumptions!$B$44*assumptions!$B$17)/12 -> 4166.6667 | E21: =(assumptions!$B$44*assumptions!$B$17)/12 -> 4166.6667 | F21: =(assumptions!$B$44*assumptions!$B$17)/12 -> 4166.6667 | G21: =(assumptions!$B$44*assumptions!$B$17)/12 -> 4166.6667 | H21: =(assumptions!$B$44*assumptions!$B$17)/12 -> 4166.6667 | I21: =(assumptions!$B$44*assumptions!$B$17)/12 -> 4166.6667 | ... M21: =(assumptions!$B$44*assumptions!$B$17)/12 -> 4166.6667 | N21: =SUM(B21:M21) -> 50000
A22: Total Marketing Expenses | B22: =SUM(B$17:B$21) -> 367166.67 | C22: =SUM(C$17:C$21) -> 367166.67 | D22: =SUM(D$17:D$21) -> 391166.67 | E22: =SUM(E$17:E$21) -> 391166.67 | F22: =SUM(F$17:F$21) -> 391166.67 | G22: =SUM(G$17:G$21) -> 391166.67 | H22: =SUM(H$17:H$21) -> 391166.67 | I22: =SUM(I$17:I$21) -> 391166.67 | ... N22: =SUM(N$17:N$21) -> 4790000
A25: Engineering | B25: Jan | C25: Feb | D25: Mar | E25: Apr | F25: May | G25: Jun | H25: Jul | I25: Aug | J25: Sep | K25: Oct | L25: Nov | M25: Dec | N25: FY 2024
A26: Salaries & Wages | B26: =(assumptions!$B$24*assumptions!$B$14)/12 -> 787500 | C26: =(assumptions!$B$24*assumptions!$B$14)/12 -> 787500 | D26: =(assumptions!$B$24*assumptions!$B$14)/12 -> 787500 | E26: =(assumptions!$B$24*assumptions!$B$14)/12 -> 787500 | F26: =(assumptions!$B$24*assumptions!$B$14)/12 -> 787500 | G26: =(assumptions!$B$24*assumptions!$B$14)/12 -> 787500 | H26: =(assumptions!$B$24*assumptions!$B$14)/12 -> 787500 | I26: =(assumptions!$B$24*assumptions!$B$14)/12 -> 787500 | ... M26: =(assumptions!$B$24*assumptions!$B$14)/12 -> 787500 | N26: =SUM(B26:M26) -> 9450000
A27: Employee Benefits | B27: =assumptions!$B$33*B26 -> 157500 | C27: =assumptions!$B$33*C26 -> 157500 | D27: =assumptions!$B$33*D26 -> 157500 | E27: =assumptions!$B$33*E26 -> 157500 | F27: =assumptions!$B$33*F26 -> 157500 | G27: =assumptions!$B$33*G26 -> 157500 | H27: =assumptions!$B$33*H26 -> 157500 | I27: =assumptions!$B$33*I26 -> 157500 | ... M27: =assumptions!$B$33*M26 -> 157500 | N27: =SUM(B27:M27) -> 1890000
A28: Cloud & Hosting | B28: =assumptions!$B$46*B4 -> 112000 | C28: =assumptions!$B$46*C4 -> 112000 | D28: =assumptions!$B$46*D4 -> 128000 | E28: =assumptions!$B$46*E4 -> 128000 | F28: =assumptions!$B$46*F4 -> 128000 | G28: =assumptions!$B$46*G4 -> 128000 | H28: =assumptions!$B$46*H4 -> 128000 | I28: =assumptions!$B$46*I4 -> 128000 | ... M28: =assumptions!$B$46*M4 -> 176000 | N28: =SUM(B28:M28) -> 1600000
A29: Software & Tools | B29: =(assumptions!$B$14*assumptions!$B$41)/12 -> 17500 | C29: =(assumptions!$B$14*assumptions!$B$41)/12 -> 17500 | D29: =(assumptions!$B$14*assumptions!$B$41)/12 -> 17500 | E29: =(assumptions!$B$14*assumptions!$B$41)/12 -> 17500 | F29: =(assumptions!$B$14*assumptions!$B$41)/12 -> 17500 | G29: =(assumptions!$B$14*assumptions!$B$41)/12 -> 17500 | H29: =(assumptions!$B$14*assumptions!$B$41)/12 -> 17500 | I29: =(assumptions!$B$14*assumptions!$B$41)/12 -> 17500 | ... M29: =(assumptions!$B$14*assumptions!$B$41)/12 -> 17500 | N29: =SUM(B29:M29) -> 210000
A30: Total Engineering Expenses | B30: =SUM(B26:B29) -> 1074500 | C30: =SUM(C26:C29) -> 1074500 | D30: =SUM(D26:D29) -> 1090500 | E30: =SUM(E26:E29) -> 1090500 | F30: =SUM(F26:F29) -> 1090500 | G30: =SUM(G26:G29) -> 1090500 | H30: =SUM(H26:H29) -> 1090500 | I30: =SUM(I26:I29) -> 1090500 | ... N30: =SUM(N26:N29) -> 13150000
A33: Product | B33: Jan | C33: Feb | D33: Mar | E33: Apr | F33: May | G33: Jun | H33: Jul | I33: Aug | J33: Sep | K33: Oct | L33: Nov | M33: Dec | N33: FY 2024
A34: Salaries & Wages | B34: =(assumptions!$B$18*assumptions!$B$28)/12 -> 156250 | C34: =(assumptions!$B$18*assumptions!$B$28)/12 -> 156250 | D34: =(assumptions!$B$18*assumptions!$B$28)/12 -> 156250 | E34: =(assumptions!$B$18*assumptions!$B$28)/12 -> 156250 | F34: =(assumptions!$B$18*assumptions!$B$28)/12 -> 156250 | G34: =(assumptions!$B$18*assumptions!$B$28)/12 -> 156250 | H34: =(assumptions!$B$18*assumptions!$B$28)/12 -> 156250 | I34: =(assumptions!$B$18*assumptions!$B$28)/12 -> 156250 | ... M34: =(assumptions!$B$18*assumptions!$B$28)/12 -> 156250 | N34: =SUM(B34:M34) -> 1875000
A35: Employee Benefits | B35: =B34*assumptions!$B$33 -> 31250 | C35: =C34*assumptions!$B$33 -> 31250 | D35: =D34*assumptions!$B$33 -> 31250 | E35: =E34*assumptions!$B$33 -> 31250 | F35: =F34*assumptions!$B$33 -> 31250 | G35: =G34*assumptions!$B$33 -> 31250 | H35: =H34*assumptions!$B$33 -> 31250 | I35: =I34*assumptions!$B$33 -> 31250 | ... M35: =M34*assumptions!$B$33 -> 31250 | N35: =SUM(B35:M35) -> 375000
A36: Software & Tools | B36: =(assumptions!$B$18*assumptions!$B$41)/12 -> 3750 | C36: =(assumptions!$B$18*assumptions!$B$41)/12 -> 3750 | D36: =(assumptions!$B$18*assumptions!$B$41)/12 -> 3750 | E36: =(assumptions!$B$18*assumptions!$B$41)/12 -> 3750 | F36: =(assumptions!$B$18*assumptions!$B$41)/12 -> 3750 | G36: =(assumptions!$B$18*assumptions!$B$41)/12 -> 3750 | H36: =(assumptions!$B$18*assumptions!$B$41)/12 -> 3750 | I36: =(assumptions!$B$18*assumptions!$B$41)/12 -> 3750 | ... M36: =(assumptions!$B$18*assumptions!$B$41)/12 -> 3750 | N36: =SUM(B36:M36) -> 45000
A37: Professional Services | B37: =assumptions!$B$47/12 -> 20833.333 | C37: =assumptions!$B$47/12 -> 20833.333 | D37: =assumptions!$B$47/12 -> 20833.333 | E37: =assumptions!$B$47/12 -> 20833.333 | F37: =assumptions!$B$47/12 -> 20833.333 | G37: =assumptions!$B$47/12 -> 20833.333 | H37: =assumptions!$B$47/12 -> 20833.333 | I37: =assumptions!$B$47/12 -> 20833.333 | ... M37: =assumptions!$B$47/12 -> 20833.333 | N37: =SUM(B37:M37) -> 250000
A38: Total Product Expenses | B38: =SUM(B34:B37) -> 212083.33 | C38: =SUM(C34:C37) -> 212083.33 | D38: =SUM(D34:D37) -> 212083.33 | E38: =SUM(E34:E37) -> 212083.33 | F38: =SUM(F34:F37) -> 212083.33 | G38: =SUM(G34:G37) -> 212083.33 | H38: =SUM(H34:H37) -> 212083.33 | I38: =SUM(I34:I37) -> 212083.33 | ... N38: =SUM(N34:N37) -> 2545000
A41: Customer Success | B41: Jan | C41: Feb | D41: Mar | E41: Apr | F41: May | G41: Jun | H41: Jul | I41: Aug | J41: Sep | K41: Oct | L41: Nov | M41: Dec | N41: FY 2024
A42: Salaries & Wages | B42: =(assumptions!$B$26*assumptions!$B$16)/12 -> 212500 | C42: =(assumptions!$B$26*assumptions!$B$16)/12 -> 212500 | D42: =(assumptions!$B$26*assumptions!$B$16)/12 -> 212500 | E42: =(assumptions!$B$26*assumptions!$B$16)/12 -> 212500 | F42: =(assumptions!$B$26*assumptions!$B$16)/12 -> 212500 | G42: =(assumptions!$B$26*assumptions!$B$16)/12 -> 212500 | H42: =(assumptions!$B$26*assumptions!$B$16)/12 -> 212500 | I42: =(assumptions!$B$26*assumptions!$B$16)/12 -> 212500 | ... M42: =(assumptions!$B$26*assumptions!$B$16)/12 -> 212500 | N42: =SUM(B42:M42) -> 2550000
A43: Employee Benefits | B43: =B42*assumptions!$B$33 -> 42500 | C43: =C42*assumptions!$B$33 -> 42500 | D43: =D42*assumptions!$B$33 -> 42500 | E43: =E42*assumptions!$B$33 -> 42500 | F43: =F42*assumptions!$B$33 -> 42500 | G43: =G42*assumptions!$B$33 -> 42500 | H43: =H42*assumptions!$B$33 -> 42500 | I43: =I42*assumptions!$B$33 -> 42500 | ... M43: =M42*assumptions!$B$33 -> 42500 | N43: =SUM(B43:M43) -> 510000
A44: Software & Tools | B44: =(assumptions!$B$16*assumptions!$B$41)/12 -> 7500 | C44: =(assumptions!$B$16*assumptions!$B$41)/12 -> 7500 | D44: =(assumptions!$B$16*assumptions!$B$41)/12 -> 7500 | E44: =(assumptions!$B$16*assumptions!$B$41)/12 -> 7500 | F44: =(assumptions!$B$16*assumptions!$B$41)/12 -> 7500 | G44: =(assumptions!$B$16*assumptions!$B$41)/12 -> 7500 | H44: =(assumptions!$B$16*assumptions!$B$41)/12 -> 7500 | I44: =(assumptions!$B$16*assumptions!$B$41)/12 -> 7500 | ... M44: =(assumptions!$B$16*assumptions!$B$41)/12 -> 7500 | N44: =SUM(B44:M44) -> 90000
A45: Travel & Entertainment | B45: =(assumptions!$B$43*assumptions!$B$16)/12 -> 5000 | C45: =(assumptions!$B$43*assumptions!$B$16)/12 -> 5000 | D45: =(assumptions!$B$43*assumptions!$B$16)/12 -> 5000 | E45: =(assumptions!$B$43*assumptions!$B$16)/12 -> 5000 | F45: =(assumptions!$B$43*assumptions!$B$16)/12 -> 5000 | G45: =(assumptions!$B$43*assumptions!$B$16)/12 -> 5000 | H45: =(assumptions!$B$43*assumptions!$B$16)/12 -> 5000 | I45: =(assumptions!$B$43*assumptions!$B$16)/12 -> 5000 | ... M45: =(assumptions!$B$43*assumptions!$B$16)/12 -> 5000 | N45: =SUM(B45:M45) -> 60000
A46: Total Customer Success Expenses | B46: =SUM(B42:B45) -> 267500 | C46: =SUM(C42:C45) -> 267500 | D46: =SUM(D42:D45) -> 267500 | E46: =SUM(E42:E45) -> 267500 | F46: =SUM(F42:F45) -> 267500 | G46: =SUM(G42:G45) -> 267500 | H46: =SUM(H42:H45) -> 267500 | I46: =SUM(I42:I45) -> 267500 | ... M46: =SUM(M42:M45) -> 267500 | N46: =SUM(B46:M46) -> 3210000
A49: G&A | B49: Jan | C49: Feb | D49: Mar | E49: Apr | F49: May | G49: Jun | H49: Jul | I49: Aug | J49: Sep | K49: Oct | L49: Nov | M49: Dec | N49: FY 2024
A50: Salaries & Wages | B50: =(assumptions!$B$19*assumptions!$B$29)/12 -> 218750 | C50: =(assumptions!$B$19*assumptions!$B$29)/12 -> 218750 | D50: =(assumptions!$B$19*assumptions!$B$29)/12 -> 218750 | E50: =(assumptions!$B$19*assumptions!$B$29)/12 -> 218750 | F50: =(assumptions!$B$19*assumptions!$B$29)/12 -> 218750 | G50: =(assumptions!$B$19*assumptions!$B$29)/12 -> 218750 | H50: =(assumptions!$B$19*assumptions!$B$29)/12 -> 218750 | I50: =(assumptions!$B$19*assumptions!$B$29)/12 -> 218750 | ... N50: =(assumptions!$B$19*assumptions!$B$29)/12 -> 218750
A51: Employee Benefits | B51: =B50*assumptions!$B$33 -> 43750 | C51: =C50*assumptions!$B$33 -> 43750 | D51: =D50*assumptions!$B$33 -> 43750 | E51: =E50*assumptions!$B$33 -> 43750 | F51: =F50*assumptions!$B$33 -> 43750 | G51: =G50*assumptions!$B$33 -> 43750 | H51: =H50*assumptions!$B$33 -> 43750 | I51: =I50*assumptions!$B$33 -> 43750 | ... N51: =N50*assumptions!$B$33 -> 43750
A52: Software & Tools | B52: =(assumptions!$B$19*assumptions!$B$41)/12 -> 6250 | C52: =(assumptions!$B$19*assumptions!$B$41)/12 -> 6250 | D52: =(assumptions!$B$19*assumptions!$B$41)/12 -> 6250 | E52: =(assumptions!$B$19*assumptions!$B$41)/12 -> 6250 | F52: =(assumptions!$B$19*assumptions!$B$41)/12 -> 6250 | G52: =(assumptions!$B$19*assumptions!$B$41)/12 -> 6250 | H52: =(assumptions!$B$19*assumptions!$B$41)/12 -> 6250 | I52: =(assumptions!$B$19*assumptions!$B$41)/12 -> 6250 | ... N52: =(assumptions!$B$19*assumptions!$B$41)/12 -> 6250
...

Sheet 2025_budget
A1: Revenue | B1: Jan | C1: Feb | D1: Mar | E1: Apr | F1: May | G1: Jun | H1: Jul | I1: Aug | J1: Sep | K1: Oct | L1: Nov | M1: Dec | N1: FY 2025
A2: Subscription Revenue | B2: =assumptions!$C$7*assumptions!B53 -> 2898000 | C2: =assumptions!$C$7*assumptions!C53 -> 2898000 | D2: =assumptions!$C$7*assumptions!D53 -> 3312000 | E2: =assumptions!$C$7*assumptions!E53 -> 3312000 | F2: =assumptions!$C$7*assumptions!F53 -> 3312000 | G2: =assumptions!$C$7*assumptions!G53 -> 3312000 | H2: =assumptions!$C$7*assumptions!H53 -> 3312000 | I2: =assumptions!$C$7*assumptions!I53 -> 3312000 | ... M2: =assumptions!$C$7*assumptions!M53 -> 4554000 | N2: =SUM(B2:M2) -> 41400000
A3: Professional Services | B3: =assumptions!$C$8*assumptions!B53 -> 322000 | C3: =assumptions!$C$8*assumptions!C53 -> 322000 | D3: =assumptions!$C$8*assumptions!D53 -> 368000 | E3: =assumptions!$C$8*assumptions!E53 -> 368000 | F3: =assumptions!$C$8*assumptions!F53 -> 368000 | G3: =assumptions!$C$8*assumptions!G53 -> 368000 | H3: =assumptions!$C$8*assumptions!H53 -> 368000 | I3: =assumptions!$C$8*assumptions!I53 -> 368000 | ... M3: =assumptions!$C$8*assumptions!M53 -> 506000 | N3: =SUM(B3:M3) -> 4600000
A4: Total Revenue | B4: =SUM(B2:B3) -> 3220000 | C4: =SUM(C2:C3) -> 3220000 | D4: =SUM(D2:D3) -> 3680000 | E4: =SUM(E2:E3) -> 3680000 | F4: =SUM(F2:F3) -> 3680000 | G4: =SUM(G2:G3) -> 3680000 | H4: =SUM(H2:H3) -> 3680000 | I4: =SUM(I2:I3) -> 3680000 | ... N4: =SUM(N2:N3) -> 46000000
A7: Sales | B7: Jan | C7: Feb | D7: Mar | E7: Apr | F7: May | G7: Jun | H7: Jul | I7: Aug | J7: Sep | K7: Oct | L7: Nov | M7: Dec | N7: FY 2025
A8: Salaries & Wages | B8: =assumptions!$C$15*assumptions!$C$25/12 -> 472083.33 | C8: =assumptions!$C$15*assumptions!$C$25/12 -> 472083.33 | D8: =assumptions!$C$15*assumptions!$C$25/12 -> 472083.33 | E8: =assumptions!$C$15*assumptions!$C$25/12 -> 472083.33 | F8: =assumptions!$C$15*assumptions!$C$25/12 -> 472083.33 | G8: =assumptions!$C$15*assumptions!$C$25/12 -> 472083.33 | H8: =assumptions!$C$15*assumptions!$C$25/12 -> 472083.33 | I8: =assumptions!$C$15*assumptions!$C$25/12 -> 472083.33 | ... M8: =assumptions!$C$15*assumptions!$C$25/12 -> 472083.33 | N8: =SUM(B8:M8) -> 5665000
A9: Employee Benefits | B9: =$B$8*assumptions!$C$33 -> 94416.667 | C9: =$B$8*assumptions!$C$33 -> 94416.667 | D9: =$B$8*assumptions!$C$33 -> 94416.667 | E9: =$B$8*assumptions!$C$33 -> 94416.667 | F9: =$B$8*assumptions!$C$33 -> 94416.667 | G9: =$B$8*assumptions!$C$33 -> 94416.667 | H9: =$B$8*assumptions!$C$33 -> 94416.667 | I9: =$B$8*assumptions!$C$33 -> 94416.667 | ... M9: =$B$8*assumptions!$C$33 -> 94416.667 | N9: =SUM(B9:M9) -> 1133000
A10: Sales Commissions | B10: =B2*assumptions!$C$40 -> 144900 | C10: =C2*assumptions!$C$40 -> 144900 | D10: =D2*assumptions!$C$40 -> 165600 | E10: =E2*assumptions!$C$40 -> 165600 | F10: =F2*assumptions!$C$40 -> 165600 | G10: =G2*assumptions!$C$40 -> 165600 | H10: =H2*assumptions!$C$40 -> 165600 | I10: =I2*assumptions!$C$40 -> 165600 | ... M10: =M2*assumptions!$C$40 -> 227700 | N10: =SUM(B10:M10) -> 2070000
A11: Software & Tools | B11: =(assumptions!$C$15*assumptions!$C$41)/12 -> 13750 | C11: =(assumptions!$C$15*assumptions!$C$41)/12 -> 13750 | D11: =(assumptions!$C$15*assumptions!$C$41)/12 -> 13750 | E11: =(assumptions!$C$15*assumptions!$C$41)/12 -> 13750 | F11: =(assumptions!$C$15*assumptions!$C$41)/12 -> 13750 | G11: =(assumptions!$C$15*assumptions!$C$41)/12 -> 13750 | H11: =(assumptions!$C$15*assumptions!$C$41)/12 -> 13750 | I11: =(assumptions!$C$15*assumptions!$C$41)/12 -> 13750 | ... M11: =(assumptions!$C$15*assumptions!$C$41)/12 -> 13750 | N11: =SUM(B11:M11) -> 165000
A12: Travel & Entertainment | B12: =(assumptions!$C$15*assumptions!$C$42)/12 -> 18333.333 | C12: =(assumptions!$C$15*assumptions!$C$42)/12 -> 18333.333 | D12: =(assumptions!$C$15*assumptions!$C$42)/12 -> 18333.333 | E12: =(assumptions!$C$15*assumptions!$C$42)/12 -> 18333.333 | F12: =(assumptions!$C$15*assumptions!$C$42)/12 -> 18333.333 | G12: =(assumptions!$C$15*assumptions!$C$42)/12 -> 18333.333 | H12: =(assumptions!$C$15*assumptions!$C$42)/12 -> 18333.333 | I12: =(assumptions!$C$15*assumptions!$C$42)/12 -> 18333.333 | ... M12: =(assumptions!$C$15*assumptions!$C$42)/12 -> 18333.333 | N12: =SUM(B12:M12) -> 220000
A13: Total Sales Expenses | B13: =SUM(B8:B12) -> 743483.33 | C13: =SUM(C8:C12) -> 743483.33 | D13: =SUM(D8:D12) -> 764183.33 | E13: =SUM(E8:E12) -> 764183.33 | F13: =SUM(F8:F12) -> 764183.33 | G13: =SUM(G8:G12) -> 764183.33 | H13: =SUM(H8:H12) -> 764183.33 | I13: =SUM(I8:I12) -> 764183.33 | ... N13: =SUM(N8:N12) -> 9253000
A16: Marketing | B16: Jan | C16: Feb | D16: Mar | E16: Apr | F16: May | G16: Jun | H16: Jul | I16: Aug | J16: Sep | K16: Oct | L16: Nov | M16: Dec | N16: FY 2025
A17: Salaries & Wages | B17: =(assumptions!$C$27*assumptions!$C$17)/12 -> 179391.67 | C17: =(assumptions!$C$27*assumptions!$C$17)/12 -> 179391.67 | D17: =(assumptions!$C$27*assumptions!$C$17)/12 -> 179391.67 | E17: =(assumptions!$C$27*assumptions!$C$17)/12 -> 179391.67 | F17: =(assumptions!$C$27*assumptions!$C$17)/12 -> 179391.67 | G17: =(assumptions!$C$27*assumptions!$C$17)/12 -> 179391.67 | H17: =(assumptions!$C$27*assumptions!$C$17)/12 -> 179391.67 | I17: =(assumptions!$C$27*assumptions!$C$17)/12 -> 179391.67 | ... M17: =(assumptions!$C$27*assumptions!$C$17)/12 -> 179391.67 | N17: =SUM(B17:M17) -> 2152700
A18: Employee Benefits | B18: =B17*assumptions!$C$33 -> 35878.333 | C18: =C17*assumptions!$C$33 -> 35878.333 | D18: =D17*assumptions!$C$33 -> 35878.333 | E18: =E17*assumptions!$C$33 -> 35878.333 | F18: =F17*assumptions!$C$33 -> 35878.333 | G18: =G17*assumptions!$C$33 -> 35878.333 | H18: =H17*assumptions!$C$33 -> 35878.333 | I18: =I17*assumptions!$C$33 -> 35878.333 | ... M18: =M17*assumptions!$C$33 -> 35878.333 | N18: =SUM(B18:M18) -> 430540
A19: Marketing & Advertising | B19: =B4*assumptions!$C$45 -> 193200 | C19: =C4*assumptions!$C$45 -> 193200 | D19: =D4*assumptions!$C$45 -> 220800 | E19: =E4*assumptions!$C$45 -> 220800 | F19: =F4*assumptions!$C$45 -> 220800 | G19: =G4*assumptions!$C$45 -> 220800 | H19: =H4*assumptions!$C$45 -> 220800 | I19: =I4*assumptions!$C$45 -> 220800 | ... M19: =M4*assumptions!$C$45 -> 303600 | N19: =SUM(B19:M19) -> 2760000
A20: Software & Tools | B20: =(assumptions!$C$17*assumptions!$C$41)/12 -> 5500 | C20: =(assumptions!$C$17*assumptions!$C$41)/12 -> 5500 | D20: =(assumptions!$C$17*assumptions!$C$41)/12 -> 5500 | E20: =(assumptions!$C$17*assumptions!$C$41)/12 -> 5500 | F20: =(assumptions!$C$17*assumptions!$C$41)/12 -> 5500 | G20: =(assumptions!$C$17*assumptions!$C$41)/12 -> 5500 | H20: =(assumptions!$C$17*assumptions!$C$41)/12 -> 5500 | I20: =(assumptions!$C$17*assumptions!$C$41)/12 -> 5500 | ... M20: =(assumptions!$C$17*assumptions!$C$41)/12 -> 5500 | N20: =SUM(B20:M20) -> 66000
A21: Travel & Entertainment | B21: =(assumptions!$C$44*assumptions!$C$17)/12 -> 4583.3333 | C21: =(assumptions!$C$44*assumptions!$C$17)/12 -> 4583.3333 | D21: =(assumptions!$C$44*assumptions!$C$17)/12 -> 4583.3333 | E21: =(assumptions!$C$44*assumptions!$C$17)/12 -> 4583.3333 | F21: =(assumptions!$C$44*assumptions!$C$17)/12 -> 4583.3333 | G21: =(assumptions!$C$44*assumptions!$C$17)/12 -> 4583.3333 | H21: =(assumptions!$C$44*assumptions!$C$17)/12 -> 4583.3333 | I21: =(assumptions!$C$44*assumptions!$C$17)/12 -> 4583.3333 | ... M21: =(assumptions!$C$44*assumptions!$C$17)/12 -> 4583.3333 | N21: =SUM(B21:M21) -> 55000
A22: Total Marketing Expenses | B22: =SUM(B$17:B$21) -> 418553.33 | C22: =SUM(C$17:C$21) -> 418553.33 | D22: =SUM(D$17:D$21) -> 446153.33 | E22: =SUM(E$17:E$21) -> 446153.33 | F22: =SUM(F$17:F$21) -> 446153.33 | G22: =SUM(G$17:G$21) -> 446153.33 | H22: =SUM(H$17:H$21) -> 446153.33 | I22: =SUM(I$17:I$21) -> 446153.33 | ... N22: =SUM(N$17:N$21) -> 5464240
A25: Engineering | B25: Jan | C25: Feb | D25: Mar | E25: Apr | F25: May | G25: Jun | H25: Jul | I25: Aug | J25: Sep | K25: Oct | L25: Nov | M25: Dec | N25: FY 2025
A26: Salaries & Wages | B26: =(assumptions!$C$24*assumptions!$C$14)/12 -> 880650 | C26: =(assumptions!$C$24*assumptions!$C$14)/12 -> 880650 | D26: =(assumptions!$C$24*assumptions!$C$14)/12 -> 880650 | E26: =(assumptions!$C$24*assumptions!$C$14)/12 -> 880650 | F26: =(assumptions!$C$24*assumptions!$C$14)/12 -> 880650 | G26: =(assumptions!$C$24*assumptions!$C$14)/12 -> 880650 | H26: =(assumptions!$C$24*assumptions!$C$14)/12 -> 880650 | I26: =(assumptions!$C$24*assumptions!$C$14)/12 -> 880650 | ... M26: =(assumptions!$C$24*assumptions!$C$14)/12 -> 880650 | N26: =SUM(B26:M26) -> 10567800
A27: Employee Benefits | B27: =assumptions!$C$33*B26 -> 176130 | C27: =assumptions!$C$33*C26 -> 176130 | D27: =assumptions!$C$33*D26 -> 176130 | E27: =assumptions!$C$33*E26 -> 176130 | F27: =assumptions!$C$33*F26 -> 176130 | G27: =assumptions!$C$33*G26 -> 176130 | H27: =assumptions!$C$33*H26 -> 176130 | I27: =assumptions!$C$33*I26 -> 176130 | ... M27: =assumptions!$C$33*M26 -> 176130 | N27: =SUM(B27:M27) -> 2113560
A28: Cloud & Hosting | B28: =assumptions!$C$46*B4 -> 128800 | C28: =assumptions!$C$46*C4 -> 128800 | D28: =assumptions!$C$46*D4 -> 147200 | E28: =assumptions!$C$46*E4 -> 147200 | F28: =assumptions!$C$46*F4 -> 147200 | G28: =assumptions!$C$46*G4 -> 147200 | H28: =assumptions!$C$46*H4 -> 147200 | I28: =assumptions!$C$46*I4 -> 147200 | ... M28: =assumptions!$C$46*M4 -> 202400 | N28: =SUM(B28:M28) -> 1840000
A29: Software & Tools | B29: =(assumptions!$C$14*assumptions!$C$41)/12 -> 19000 | C29: =(assumptions!$C$14*assumptions!$C$41)/12 -> 19000 | D29: =(assumptions!$C$14*assumptions!$C$41)/12 -> 19000 | E29: =(assumptions!$C$14*assumptions!$C$41)/12 -> 19000 | F29: =(assumptions!$C$14*assumptions!$C$41)/12 -> 19000 | G29: =(assumptions!$C$14*assumptions!$C$41)/12 -> 19000 | H29: =(assumptions!$C$14*assumptions!$C$41)/12 -> 19000 | I29: =(assumptions!$C$14*assumptions!$C$41)/12 -> 19000 | ... M29: =(assumptions!$C$14*assumptions!$C$41)/12 -> 19000 | N29: =SUM(B29:M29) -> 228000
A30: Total Engineering Expenses | B30: =SUM(B26:B29) -> 1204580 | C30: =SUM(C26:C29) -> 1204580 | D30: =SUM(D26:D29) -> 1222980 | E30: =SUM(E26:E29) -> 1222980 | F30: =SUM(F26:F29) -> 1222980 | G30: =SUM(G26:G29) -> 1222980 | H30: =SUM(H26:H29) -> 1222980 | I30: =SUM(I26:I29) -> 1222980 | ... N30: =SUM(N26:N29) -> 14749360
A33: Product | B33: Jan | C33: Feb | D33: Mar | E33: Apr | F33: May | G33: Jun | H33: Jul | I33: Aug | J33: Sep | K33: Oct | L33: Nov | M33: Dec | N33: FY 2025
A34: Salaries & Wages | B34: =(assumptions!$C$18*assumptions!$C$28)/12 -> 182395.83 | C34: =(assumptions!$C$18*assumptions!$C$28)/12 -> 182395.83 | D34: =(assumptions!$C$18*assumptions!$C$28)/12 -> 182395.83 | E34: =(assumptions!$C$18*assumptions!$C$28)/12 -> 182395.83 | F34: =(assumptions!$C$18*assumptions!$C$28)/12 -> 182395.83 | G34: =(assumptions!$C$18*assumptions!$C$28)/12 -> 182395.83 | H34: =(assumptions!$C$18*assumptions!$C$28)/12 -> 182395.83 | I34: =(assumptions!$C$18*assumptions!$C$28)/12 -> 182395.83 | ... M34: =(assumptions!$C$18*assumptions!$C$28)/12 -> 182395.83 | N34: =SUM(B34:M34) -> 2188750
A35: Employee Benefits | B35: =B34*assumptions!$C$33 -> 36479.167 | C35: =C34*assumptions!$C$33 -> 36479.167 | D35: =D34*assumptions!$C$33 -> 36479.167 | E35: =E34*assumptions!$C$33 -> 36479.167 | F35: =F34*assumptions!$C$33 -> 36479.167 | G35: =G34*assumptions!$C$33 -> 36479.167 | H35: =H34*assumptions!$C$33 -> 36479.167 | I35: =I34*assumptions!$C$33 -> 36479.167 | ... M35: =M34*assumptions!$C$33 -> 36479.167 | N35: =SUM(B35:M35) -> 437750
A36: Software & Tools | B36: =(assumptions!$C$18*assumptions!$C$41)/12 -> 4250 | C36: =(assumptions!$C$18*assumptions!$C$41)/12 -> 4250 | D36: =(assumptions!$C$18*assumptions!$C$41)/12 -> 4250 | E36: =(assumptions!$C$18*assumptions!$C$41)/12 -> 4250 | F36: =(assumptions!$C$18*assumptions!$C$41)/12 -> 4250 | G36: =(assumptions!$C$18*assumptions!$C$41)/12 -> 4250 | H36: =(assumptions!$C$18*assumptions!$C$41)/12 -> 4250 | I36: =(assumptions!$C$18*assumptions!$C$41)/12 -> 4250 | ... M36: =(assumptions!$C$18*assumptions!$C$41)/12 -> 4250 | N36: =SUM(B36:M36) -> 51000
A37: Professional Services | B37: =assumptions!$C$47/12 -> 25000 | C37: =assumptions!$C$47/12 -> 25000 | D37: =assumptions!$C$47/12 -> 25000 | E37: =assumptions!$C$47/12 -> 25000 | F37: =assumptions!$C$47/12 -> 25000 | G37: =assumptions!$C$47/12 -> 25000 | H37: =assumptions!$C$47/12 -> 25000 | I37: =assumptions!$C$47/12 -> 25000 | ... M37: =assumptions!$C$47/12 -> 25000 | N37: =SUM(B37:M37) -> 300000
A38: Total Product Expenses | B38: =SUM(B34:B37) -> 248125 | C38: =SUM(C34:C37) -> 248125 | D38: =SUM(D34:D37) -> 248125 | E38: =SUM(E34:E37) -> 248125 | F38: =SUM(F34:F37) -> 248125 | G38: =SUM(G34:G37) -> 248125 | H38: =SUM(H34:H37) -> 248125 | I38: =SUM(I34:I37) -> 248125 | ... N38: =SUM(N34:N37) -> 2977500
A41: Customer Success | B41: Jan | C41: Feb | D41: Mar | E41: Apr | F41: May | G41: Jun | H41: Jul | I41: Aug | J41: Sep | K41: Oct | L41: Nov | M41: Dec | N41: FY 2025
A42: Salaries & Wages | B42: =(assumptions!$C$26*assumptions!$C$16)/12 -> 240762.5 | C42: =(assumptions!$C$26*assumptions!$C$16)/12 -> 240762.5 | D42: =(assumptions!$C$26*assumptions!$C$16)/12 -> 240762.5 | E42: =(assumptions!$C$26*assumptions!$C$16)/12 -> 240762.5 | F42: =(assumptions!$C$26*assumptions!$C$16)/12 -> 240762.5 | G42: =(assumptions!$C$26*assumptions!$C$16)/12 -> 240762.5 | H42: =(assumptions!$C$26*assumptions!$C$16)/12 -> 240762.5 | I42: =(assumptions!$C$26*assumptions!$C$16)/12 -> 240762.5 | ... M42: =(assumptions!$C$26*assumptions!$C$16)/12 -> 240762.5 | N42: =SUM(B42:M42) -> 2889150
A43: Employee Benefits | B43: =B42*assumptions!$C$33 -> 48152.5 | C43: =C42*assumptions!$C$33 -> 48152.5 | D43: =D42*assumptions!$C$33 -> 48152.5 | E43: =E42*assumptions!$C$33 -> 48152.5 | F43: =F42*assumptions!$C$33 -> 48152.5 | G43: =G42*assumptions!$C$33 -> 48152.5 | H43: =H42*assumptions!$C$33 -> 48152.5 | I43: =I42*assumptions!$C$33 -> 48152.5 | ... M43: =M42*assumptions!$C$33 -> 48152.5 | N43: =SUM(B43:M43) -> 577830
A44: Software & Tools | B44: =(assumptions!$C$16*assumptions!$C$41)/12 -> 8250 | C44: =(assumptions!$C$16*assumptions!$C$41)/12 -> 8250 | D44: =(assumptions!$C$16*assumptions!$C$41)/12 -> 8250 | E44: =(assumptions!$C$16*assumptions!$C$41)/12 -> 8250 | F44: =(assumptions!$C$16*assumptions!$C$41)/12 -> 8250 | G44: =(assumptions!$C$16*assumptions!$C$41)/12 -> 8250 | H44: =(assumptions!$C$16*assumptions!$C$41)/12 -> 8250 | I44: =(assumptions!$C$16*assumptions!$C$41)/12 -> 8250 | ... M44: =(assumptions!$C$16*assumptions!$C$41)/12 -> 8250 | N44: =SUM(B44:M44) -> 99000
A45: Travel & Entertainment | B45: =(assumptions!$C$43*assumptions!$C$16)/12 -> 5500 | C45: =(assumptions!$C$43*assumptions!$C$16)/12 -> 5500 | D45: =(assumptions!$C$43*assumptions!$C$16)/12 -> 5500 | E45: =(assumptions!$C$43*assumptions!$C$16)/12 -> 5500 | F45: =(assumptions!$C$43*assumptions!$C$16)/12 -> 5500 | G45: =(assumptions!$C$43*assumptions!$C$16)/12 -> 5500 | H45: =(assumptions!$C$43*assumptions!$C$16)/12 -> 5500 | I45: =(assumptions!$C$43*assumptions!$C$16)/12 -> 5500 | ... M45: =(assumptions!$C$43*assumptions!$C$16)/12 -> 5500 | N45: =SUM(B45:M45) -> 66000
A46: Total Customer Success Expenses | B46: =SUM(B42:B45) -> 302665 | C46: =SUM(C42:C45) -> 302665 | D46: =SUM(D42:D45) -> 302665 | E46: =SUM(E42:E45) -> 302665 | F46: =SUM(F42:F45) -> 302665 | G46: =SUM(G42:G45) -> 302665 | H46: =SUM(H42:H45) -> 302665 | I46: =SUM(I42:I45) -> 302665 | ... M46: =SUM(M42:M45) -> 302665 | N46: =SUM(B46:M46) -> 3631980
A49: G&A | B49: Jan | C49: Feb | D49: Mar | E49: Apr | F49: May | G49: Jun | H49: Jul | I49: Aug | J49: Sep | K49: Oct | L49: Nov | M49: Dec | N49: FY 2025
A50: Salaries & Wages | B50: =(assumptions!$C$19*assumptions!$C$29)/12 -> 234325 | C50: =(assumptions!$C$19*assumptions!$C$29)/12 -> 234325 | D50: =(assumptions!$C$19*assumptions!$C$29)/12 -> 234325 | E50: =(assumptions!$C$19*assumptions!$C$29)/12 -> 234325 | F50: =(assumptions!$C$19*assumptions!$C$29)/12 -> 234325 | G50: =(assumptions!$C$19*assumptions!$C$29)/12 -> 234325 | H50: =(assumptions!$C$19*assumptions!$C$29)/12 -> 234325 | I50: =(assumptions!$C$19*assumptions!$C$29)/12 -> 234325 | ... M50: =(assumptions!$C$19*assumptions!$C$29)/12 -> 234325 | N50: =SUM(B50:M50) -> 2811900
A51: Employee Benefits | B51: =B50*assumptions!$C$33 -> 46865 | C51: =C50*assumptions!$C$33 -> 46865 | D51: =D50*assumptions!$C$33 -> 46865 | E51: =E50*assumptions!$C$33 -> 46865 | F51: =F50*assumptions!$C$33 -> 46865 | G51: =G50*assumptions!$C$33 -> 46865 | H51: =H50*assumptions!$C$33 -> 46865 | I51: =I50*assumptions!$C$33 -> 46865 | ... M51: =M50*assumptions!$C$33 -> 46865 | N51: =SUM(B51:M51) -> 562380
A52: Software & Tools | B52: =(assumptions!$C$19*assumptions!$C$41)/12 -> 6500 | C52: =(assumptions!$C$19*assumptions!$C$41)/12 -> 6500 | D52: =(assumptions!$C$19*assumptions!$C$41)/12 -> 6500 | E52: =(assumptions!$C$19*assumptions!$C$41)/12 -> 6500 | F52: =(assumptions!$C$19*assumptions!$C$41)/12 -> 6500 | G52: =(assumptions!$C$19*assumptions!$C$41)/12 -> 6500 | H52: =(assumptions!$C$19*assumptions!$C$41)/12 -> 6500 | I52: =(assumptions!$C$19*assumptions!$C$41)/12 -> 6500 | ... M52: =(assumptions!$C$19*assumptions!$C$41)/12 -> 6500 | N52: =SUM(B52:M52) -> 78000
...

Sheet 2026_budget
A1: Revenue | B1: Jan | C1: Feb | D1: Mar | E1: Apr | F1: May | G1: Jun | H1: Jul | I1: Aug | J1: Sep | K1: Oct | L1: Nov | M1: Dec | N1: FY 2026
A2: Subscription Revenue | B2: =assumptions!$D$7*assumptions!B53 -> 3332700 | C2: =assumptions!$D$7*assumptions!C53 -> 3332700 | D2: =assumptions!$D$7*assumptions!D53 -> 3808800 | E2: =assumptions!$D$7*assumptions!E53 -> 3808800 | F2: =assumptions!$D$7*assumptions!F53 -> 3808800 | G2: =assumptions!$D$7*assumptions!G53 -> 3808800 | H2: =assumptions!$D$7*assumptions!H53 -> 3808800 | I2: =assumptions!$D$7*assumptions!I53 -> 3808800 | ... M2: =assumptions!$D$7*assumptions!M53 -> 5237100 | N2: =SUM(B2:M2) -> 47610000
A3: Professional Services | B3: =assumptions!$D$8*assumptions!B53 -> 370300 | C3: =assumptions!$D$8*assumptions!C53 -> 370300 | D3: =assumptions!$D$8*assumptions!D53 -> 423200 | E3: =assumptions!$D$8*assumptions!E53 -> 423200 | F3: =assumptions!$D$8*assumptions!F53 -> 423200 | G3: =assumptions!$D$8*assumptions!G53 -> 423200 | H3: =assumptions!$D$8*assumptions!H53 -> 423200 | I3: =assumptions!$D$8*assumptions!I53 -> 423200 | ... M3: =assumptions!$D$8*assumptions!M53 -> 581900 | N3: =SUM(B3:M3) -> 5290000
A4: Total Revenue | B4: =SUM(B2:B3) -> 3703000 | C4: =SUM(C2:C3) -> 3703000 | D4: =SUM(D2:D3) -> 4232000 | E4: =SUM(E2:E3) -> 4232000 | F4: =SUM(F2:F3) -> 4232000 | G4: =SUM(G2:G3) -> 4232000 | H4: =SUM(H2:H3) -> 4232000 | I4: =SUM(I2:I3) -> 4232000 | ... N4: =SUM(N2:N3) -> 52900000
A7: Sales | B7: Jan | C7: Feb | D7: Mar | E7: Apr | F7: May | G7: Jun | H7: Jul | I7: Aug | J7: Sep | K7: Oct | L7: Nov | M7: Dec | N7: FY 2026
A8: Salaries & Wages | B8: =assumptions!$D$15*assumptions!$D$25/12 -> 530450 | C8: =assumptions!$D$15*assumptions!$D$25/12 -> 530450 | D8: =assumptions!$D$15*assumptions!$D$25/12 -> 530450 | E8: =assumptions!$D$15*assumptions!$D$25/12 -> 530450 | F8: =assumptions!$D$15*assumptions!$D$25/12 -> 530450 | G8: =assumptions!$D$15*assumptions!$D$25/12 -> 530450 | H8: =assumptions!$D$15*assumptions!$D$25/12 -> 530450 | I8: =assumptions!$D$15*assumptions!$D$25/12 -> 530450 | ... M8: =assumptions!$D$15*assumptions!$D$25/12 -> 530450 | N8: =SUM(B8:M8) -> 6365400
A9: Employee Benefits | B9: =$B$8*assumptions!$D$33 -> 106090 | C9: =$B$8*assumptions!$D$33 -> 106090 | D9: =$B$8*assumptions!$D$33 -> 106090 | E9: =$B$8*assumptions!$D$33 -> 106090 | F9: =$B$8*assumptions!$D$33 -> 106090 | G9: =$B$8*assumptions!$D$33 -> 106090 | H9: =$B$8*assumptions!$D$33 -> 106090 | I9: =$B$8*assumptions!$D$33 -> 106090 | ... M9: =$B$8*assumptions!$D$33 -> 106090 | N9: =SUM(B9:M9) -> 1273080
A10: Sales Commissions | B10: =B2*assumptions!$D$40 -> 166635 | C10: =C2*assumptions!$D$40 -> 166635 | D10: =D2*assumptions!$D$40 -> 190440 | E10: =E2*assumptions!$D$40 -> 190440 | F10: =F2*assumptions!$D$40 -> 190440 | G10: =G2*assumptions!$D$40 -> 190440 | H10: =H2*assumptions!$D$40 -> 190440 | I10: =I2*assumptions!$D$40 -> 190440 | ... M10: =M2*assumptions!$D$40 -> 261855 | N10: =SUM(B10:M10) -> 2380500
A11: Software & Tools | B11: =(assumptions!$D$15*assumptions!$D$41)/12 -> 15000 | C11: =(assumptions!$D$15*assumptions!$D$41)/12 -> 15000 | D11: =(assumptions!$D$15*assumptions!$D$41)/12 -> 15000 | E11: =(assumptions!$D$15*assumptions!$D$41)/12 -> 15000 | F11: =(assumptions!$D$15*assumptions!$D$41)/12 -> 15000 | G11: =(assumptions!$D$15*assumptions!$D$41)/12 -> 15000 | H11: =(assumptions!$D$15*assumptions!$D$41)/12 -> 15000 | I11: =(assumptions!$D$15*assumptions!$D$41)/12 -> 15000 | ... M11: =(assumptions!$D$15*assumptions!$D$41)/12 -> 15000 | N11: =SUM(B11:M11) -> 180000
A12: Travel & Entertainment | B12: =(assumptions!$D$15*assumptions!$D$42)/12 -> 20000 | C12: =(assumptions!$D$15*assumptions!$D$42)/12 -> 20000 | D12: =(assumptions!$D$15*assumptions!$D$42)/12 -> 20000 | E12: =(assumptions!$D$15*assumptions!$D$42)/12 -> 20000 | F12: =(assumptions!$D$15*assumptions!$D$42)/12 -> 20000 | G12: =(assumptions!$D$15*assumptions!$D$42)/12 -> 20000 | H12: =(assumptions!$D$15*assumptions!$D$42)/12 -> 20000 | I12: =(assumptions!$D$15*assumptions!$D$42)/12 -> 20000 | ... M12: =(assumptions!$D$15*assumptions!$D$42)/12 -> 20000 | N12: =SUM(B12:M12) -> 240000
A13: Total Sales Expenses | B13: =SUM(B8:B12) -> 838175 | C13: =SUM(C8:C12) -> 838175 | D13: =SUM(D8:D12) -> 861980 | E13: =SUM(E8:E12) -> 861980 | F13: =SUM(F8:F12) -> 861980 | G13: =SUM(G8:G12) -> 861980 | H13: =SUM(H8:H12) -> 861980 | I13: =SUM(I8:I12) -> 861980 | ... N13: =SUM(N8:N12) -> 10438980
A16: Marketing | B16: Jan | C16: Feb | D16: Mar | E16: Apr | F16: May | G16: Jun | H16: Jul | I16: Aug | J16: Sep | K16: Oct | L16: Nov | M16: Dec | N16: FY 2026
A17: Salaries & Wages | B17: =(assumptions!$D$27*assumptions!$D$17)/12 -> 201571 | C17: =(assumptions!$D$27*assumptions!$D$17)/12 -> 201571 | D17: =(assumptions!$D$27*assumptions!$D$17)/12 -> 201571 | E17: =(assumptions!$D$27*assumptions!$D$17)/12 -> 201571 | F17: =(assumptions!$D$27*assumptions!$D$17)/12 -> 201571 | G17: =(assumptions!$D$27*assumptions!$D$17)/12 -> 201571 | H17: =(assumptions!$D$27*assumptions!$D$17)/12 -> 201571 | I17: =(assumptions!$D$27*assumptions!$D$17)/12 -> 201571 | ... M17: =(assumptions!$D$27*assumptions!$D$17)/12 -> 201571 | N17: =SUM(B17:M17) -> 2418852
A18: Employee Benefits | B18: =B17*assumptions!$D$33 -> 40314.2 | C18: =C17*assumptions!$D$33 -> 40314.2 | D18: =D17*assumptions!$D$33 -> 40314.2 | E18: =E17*assumptions!$D$33 -> 40314.2 | F18: =F17*assumptions!$D$33 -> 40314.2 | G18: =G17*assumptions!$D$33 -> 40314.2 | H18: =H17*assumptions!$D$33 -> 40314.2 | I18: =I17*assumptions!$D$33 -> 40314.2 | ... M18: =M17*assumptions!$D$33 -> 40314.2 | N18: =SUM(B18:M18) -> 483770.4
A19: Marketing & Advertising | B19: =B4*assumptions!$D$45 -> 222180 | C19: =C4*assumptions!$D$45 -> 222180 | D19: =D4*assumptions!$D$45 -> 253920 | E19: =E4*assumptions!$D$45 -> 253920 | F19: =F4*assumptions!$D$45 -> 253920 | G19: =G4*assumptions!$D$45 -> 253920 | H19: =H4*assumptions!$D$45 -> 253920 | I19: =I4*assumptions!$D$45 -> 253920 | ... M19: =M4*assumptions!$D$45 -> 349140 | N19: =SUM(B19:M19) -> 3174000
A20: Software & Tools | B20: =(assumptions!$D$17*assumptions!$D$41)/12 -> 6000 | C20: =(assumptions!$D$17*assumptions!$D$41)/12 -> 6000 | D20: =(assumptions!$D$17*assumptions!$D$41)/12 -> 6000 | E20: =(assumptions!$D$17*assumptions!$D$41)/12 -> 6000 | F20: =(assumptions!$D$17*assumptions!$D$41)/12 -> 6000 | G20: =(assumptions!$D$17*assumptions!$D$41)/12 -> 6000 | H20: =(assumptions!$D$17*assumptions!$D$41)/12 -> 6000 | I20: =(assumptions!$D$17*assumptions!$D$41)/12 -> 6000 | ... M20: =(assumptions!$D$17*assumptions!$D$41)/12 -> 6000 | N20: =SUM(B20:M20) -> 72000
A21: Travel & Entertainment | B21: =(assumptions!$D$44*assumptions!$D$17)/12 -> 5000 | C21: =(assumptions!$D$44*assumptions!$D$17)/12 -> 5000 | D21: =(assumptions!$D$44*assumptions!$D$17)/12 -> 5000 | E21: =(assumptions!$D$44*assumptions!$D$17)/12 -> 5000 | F21: =(assumptions!$D$44*assumptions!$D$17)/12 -> 5000 | G21: =(assumptions!$D$44*assumptions!$D$17)/12 -> 5000 | H21: =(assumptions!$D$44*assumptions!$D$17)/12 -> 5000 | I21: =(assumptions!$D$44*assumptions!$D$17)/12 -> 5000 | ... M21: =(assumptions!$D$44*assumptions!$D$17)/12 -> 5000 | N21: =SUM(B21:M21) -> 60000
A22: Total Marketing Expenses | B22: =SUM(B$17:B$21) -> 475065.2 | C22: =SUM(C$17:C$21) -> 475065.2 | D22: =SUM(D$17:D$21) -> 506805.2 | E22: =SUM(E$17:E$21) -> 506805.2 | F22: =SUM(F$17:F$21) -> 506805.2 | G22: =SUM(G$17:G$21) -> 506805.2 | H22: =SUM(H$17:H$21) -> 506805.2 | I22: =SUM(I$17:I$21) -> 506805.2 | ... N22: =SUM(N$17:N$21) -> 6208622.4
A25: Engineering | B25: Jan | C25: Feb | D25: Mar | E25: Apr | F25: May | G25: Jun | H25: Jul | I25: Aug | J25: Sep | K25: Oct | L25: Nov | M25: Dec | N25: FY 2026
A26: Salaries & Wages | B26: =(assumptions!$D$24*assumptions!$D$14)/12 -> 978680.25 | C26: =(assumptions!$D$24*assumptions!$D$14)/12 -> 978680.25 | D26: =(assumptions!$D$24*assumptions!$D$14)/12 -> 978680.25 | E26: =(assumptions!$D$24*assumptions!$D$14)/12 -> 978680.25 | F26: =(assumptions!$D$24*assumptions!$D$14)/12 -> 978680.25 | G26: =(assumptions!$D$24*assumptions!$D$14)/12 -> 978680.25 | H26: =(assumptions!$D$24*assumptions!$D$14)/12 -> 978680.25 | I26: =(assumptions!$D$24*assumptions!$D$14)/12 -> 978680.25 | ... M26: =(assumptions!$D$24*assumptions!$D$14)/12 -> 978680.25 | N26: =SUM(B26:M26) -> 11744163
A27: Employee Benefits | B27: =assumptions!$D$33*B26 -> 195736.05 | C27: =assumptions!$D$33*C26 -> 195736.05 | D27: =assumptions!$D$33*D26 -> 195736.05 | E27: =assumptions!$D$33*E26 -> 195736.05 | F27: =assumptions!$D$33*F26 -> 195736.05 | G27: =assumptions!$D$33*G26 -> 195736.05 | H27: =assumptions!$D$33*H26 -> 195736.05 | I27: =assumptions!$D$33*I26 -> 195736.05 | ... M27: =assumptions!$D$33*M26 -> 195736.05 | N27: =SUM(B27:M27) -> 2348832.6
A28: Cloud & Hosting | B28: =assumptions!$D$46*B4 -> 148120 | C28: =assumptions!$D$46*C4 -> 148120 | D28: =assumptions!$D$46*D4 -> 169280 | E28: =assumptions!$D$46*E4 -> 169280 | F28: =assumptions!$D$46*F4 -> 169280 | G28: =assumptions!$D$46*G4 -> 169280 | H28: =assumptions!$D$46*H4 -> 169280 | I28: =assumptions!$D$46*I4 -> 169280 | ... M28: =assumptions!$D$46*M4 -> 232760 | N28: =SUM(B28:M28) -> 2116000
A29: Software & Tools | B29: =(assumptions!$D$14*assumptions!$D$41)/12 -> 20500 | C29: =(assumptions!$D$14*assumptions!$D$41)/12 -> 20500 | D29: =(assumptions!$D$14*assumptions!$D$41)/12 -> 20500 | E29: =(assumptions!$D$14*assumptions!$D$41)/12 -> 20500 | F29: =(assumptions!$D$14*assumptions!$D$41)/12 -> 20500 | G29: =(assumptions!$D$14*assumptions!$D$41)/12 -> 20500 | H29: =(assumptions!$D$14*assumptions!$D$41)/12 -> 20500 | I29: =(assumptions!$D$14*assumptions!$D$41)/12 -> 20500 | ... M29: =(assumptions!$D$14*assumptions!$D$41)/12 -> 20500 | N29: =SUM(B29:M29) -> 246000
A30: Total Engineering Expenses | B30: =SUM(B26:B29) -> 1343036.3 | C30: =SUM(C26:C29) -> 1343036.3 | D30: =SUM(D26:D29) -> 1364196.3 | E30: =SUM(E26:E29) -> 1364196.3 | F30: =SUM(F26:F29) -> 1364196.3 | G30: =SUM(G26:G29) -> 1364196.3 | H30: =SUM(H26:H29) -> 1364196.3 | I30: =SUM(I26:I29) -> 1364196.3 | ... N30: =SUM(N26:N29) -> 16454996
A33: Product | B33: Jan | C33: Feb | D33: Mar | E33: Apr | F33: May | G33: Jun | H33: Jul | I33: Aug | J33: Sep | K33: Oct | L33: Nov | M33: Dec | N33: FY 2026
A34: Salaries & Wages | B34: =(assumptions!$D$18*assumptions!$D$28)/12 -> 209969.79 | C34: =(assumptions!$D$18*assumptions!$D$28)/12 -> 209969.79 | D34: =(assumptions!$D$18*assumptions!$D$28)/12 -> 209969.79 | E34: =(assumptions!$D$18*assumptions!$D$28)/12 -> 209969.79 | F34: =(assumptions!$D$18*assumptions!$D$28)/12 -> 209969.79 | G34: =(assumptions!$D$18*assumptions!$D$28)/12 -> 209969.79 | H34: =(assumptions!$D$18*assumptions!$D$28)/12 -> 209969.79 | I34: =(assumptions!$D$18*assumptions!$D$28)/12 -> 209969.79 | ... M34: =(assumptions!$D$18*assumptions!$D$28)/12 -> 209969.79 | N34: =SUM(B34:M34) -> 2519637.5
A35: Employee Benefits | B35: =B34*assumptions!$D$33 -> 41993.958 | C35: =C34*assumptions!$D$33 -> 41993.958 | D35: =D34*assumptions!$D$33 -> 41993.958 | E35: =E34*assumptions!$D$33 -> 41993.958 | F35: =F34*assumptions!$D$33 -> 41993.958 | G35: =G34*assumptions!$D$33 -> 41993.958 | H35: =H34*assumptions!$D$33 -> 41993.958 | I35: =I34*assumptions!$D$33 -> 41993.958 | ... M35: =M34*assumptions!$D$33 -> 41993.958 | N35: =SUM(B35:M35) -> 503927.5
A36: Software & Tools | B36: =(assumptions!$D$18*assumptions!$D$41)/12 -> 4750 | C36: =(assumptions!$D$18*assumptions!$D$41)/12 -> 4750 | D36: =(assumptions!$D$18*assumptions!$D$41)/12 -> 4750 | E36: =(assumptions!$D$18*assumptions!$D$41)/12 -> 4750 | F36: =(assumptions!$D$18*assumptions!$D$41)/12 -> 4750 | G36: =(assumptions!$D$18*assumptions!$D$41)/12 -> 4750 | H36: =(assumptions!$D$18*assumptions!$D$41)/12 -> 4750 | I36: =(assumptions!$D$18*assumptions!$D$41)/12 -> 4750 | ... M36: =(assumptions!$D$18*assumptions!$D$41)/12 -> 4750 | N36: =SUM(B36:M36) -> 57000
A37: Professional Services | B37: =assumptions!$D$47/12 -> 27083.333 | C37: =assumptions!$D$47/12 -> 27083.333 | D37: =assumptions!$D$47/12 -> 27083.333 | E37: =assumptions!$D$47/12 -> 27083.333 | F37: =assumptions!$D$47/12 -> 27083.333 | G37: =assumptions!$D$47/12 -> 27083.333 | H37: =assumptions!$D$47/12 -> 27083.333 | I37: =assumptions!$D$47/12 -> 27083.333 | ... M37: =assumptions!$D$47/12 -> 27083.333 | N37: =SUM(B37:M37) -> 325000
A38: Total Product Expenses | B38: =SUM(B34:B37) -> 283797.08 | C38: =SUM(C34:C37) -> 283797.08 | D38: =SUM(D34:D37) -> 283797.08 | E38: =SUM(E34:E37) -> 283797.08 | F38: =SUM(F34:F37) -> 283797.08 | G38: =SUM(G34:G37) -> 283797.08 | H38: =SUM(H34:H37) -> 283797.08 | I38: =SUM(I34:I37) -> 283797.08 | ... N38: =SUM(N34:N37) -> 3405565
A41: Customer Success | B41: Jan | C41: Feb | D41: Mar | E41: Apr | F41: May | G41: Jun | H41: Jul | I41: Aug | J41: Sep | K41: Oct | L41: Nov | M41: Dec | N41: FY 2026
A42: Salaries & Wages | B42: =(assumptions!$D$26*assumptions!$D$16)/12 -> 270529.5 | C42: =(assumptions!$D$26*assumptions!$D$16)/12 -> 270529.5 | D42: =(assumptions!$D$26*assumptions!$D$16)/12 -> 270529.5 | E42: =(assumptions!$D$26*assumptions!$D$16)/12 -> 270529.5 | F42: =(assumptions!$D$26*assumptions!$D$16)/12 -> 270529.5 | G42: =(assumptions!$D$26*assumptions!$D$16)/12 -> 270529.5 | H42: =(assumptions!$D$26*assumptions!$D$16)/12 -> 270529.5 | I42: =(assumptions!$D$26*assumptions!$D$16)/12 -> 270529.5 | ... M42: =(assumptions!$D$26*assumptions!$D$16)/12 -> 270529.5 | N42: =SUM(B42:M42) -> 3246354
A43: Employee Benefits | B43: =B42*assumptions!$D$33 -> 54105.9 | C43: =C42*assumptions!$D$33 -> 54105.9 | D43: =D42*assumptions!$D$33 -> 54105.9 | E43: =E42*assumptions!$D$33 -> 54105.9 | F43: =F42*assumptions!$D$33 -> 54105.9 | G43: =G42*assumptions!$D$33 -> 54105.9 | H43: =H42*assumptions!$D$33 -> 54105.9 | I43: =I42*assumptions!$D$33 -> 54105.9 | ... M43: =M42*assumptions!$D$33 -> 54105.9 | N43: =SUM(B43:M43) -> 649270.8
A44: Software & Tools | B44: =(assumptions!$D$16*assumptions!$D$41)/12 -> 9000 | C44: =(assumptions!$D$16*assumptions!$D$41)/12 -> 9000 | D44: =(assumptions!$D$16*assumptions!$D$41)/12 -> 9000 | E44: =(assumptions!$D$16*assumptions!$D$41)/12 -> 9000 | F44: =(assumptions!$D$16*assumptions!$D$41)/12 -> 9000 | G44: =(assumptions!$D$16*assumptions!$D$41)/12 -> 9000 | H44: =(assumptions!$D$16*assumptions!$D$41)/12 -> 9000 | I44: =(assumptions!$D$16*assumptions!$D$41)/12 -> 9000 | ... M44: =(assumptions!$D$16*assumptions!$D$41)/12 -> 9000 | N44: =SUM(B44:M44) -> 108000
A45: Travel & Entertainment | B45: =(assumptions!$D$43*assumptions!$D$16)/12 -> 6000 | C45: =(assumptions!$D$43*assumptions!$D$16)/12 -> 6000 | D45: =(assumptions!$D$43*assumptions!$D$16)/12 -> 6000 | E45: =(assumptions!$D$43*assumptions!$D$16)/12 -> 6000 | F45: =(assumptions!$D$43*assumptions!$D$16)/12 -> 6000 | G45: =(assumptions!$D$43*assumptions!$D$16)/12 -> 6000 | H45: =(assumptions!$D$43*assumptions!$D$16)/12 -> 6000 | I45: =(assumptions!$D$43*assumptions!$D$16)/12 -> 6000 | ... M45: =(assumptions!$D$43*assumptions!$D$16)/12 -> 6000 | N45: =SUM(B45:M45) -> 72000
A46: Total Customer Success Expenses | B46: =SUM(B42:B45) -> 339635.4 | C46: =SUM(C42:C45) -> 339635.4 | D46: =SUM(D42:D45) -> 339635.4 | E46: =SUM(E42:E45) -> 339635.4 | F46: =SUM(F42:F45) -> 339635.4 | G46: =SUM(G42:G45) -> 339635.4 | H46: =SUM(H42:H45) -> 339635.4 | I46: =SUM(I42:I45) -> 339635.4 | ... M46: =SUM(M42:M45) -> 339635.4 | N46: =SUM(B46:M46) -> 4075624.8
A49: G&A | B49: Jan | C49: Feb | D49: Mar | E49: Apr | F49: May | G49: Jun | H49: Jul | I49: Aug | J49: Sep | K49: Oct | L49: Nov | M49: Dec | N49: FY 2026
A50: Salaries & Wages | B50: =(assumptions!$D$19*assumptions!$D$29)/12 -> 250637.62 | C50: =(assumptions!$D$19*assumptions!$D$29)/12 -> 250637.62 | D50: =(assumptions!$D$19*assumptions!$D$29)/12 -> 250637.62 | E50: =(assumptions!$D$19*assumptions!$D$29)/12 -> 250637.62 | F50: =(assumptions!$D$19*assumptions!$D$29)/12 -> 250637.62 | G50: =(assumptions!$D$19*assumptions!$D$29)/12 -> 250637.62 | H50: =(assumptions!$D$19*assumptions!$D$29)/12 -> 250637.62 | I50: =(assumptions!$D$19*assumptions!$D$29)/12 -> 250637.62 | ... M50: =(assumptions!$D$19*assumptions!$D$29)/12 -> 250637.62 | N50: =SUM(B50:M50) -> 3007651.5
A51: Employee Benefits | B51: =B50*assumptions!$D$33 -> 50127.525 | C51: =C50*assumptions!$D$33 -> 50127.525 | D51: =D50*assumptions!$D$33 -> 50127.525 | E51: =E50*assumptions!$D$33 -> 50127.525 | F51: =F50*assumptions!$D$33 -> 50127.525 | G51: =G50*assumptions!$D$33 -> 50127.525 | H51: =H50*assumptions!$D$33 -> 50127.525 | I51: =I50*assumptions!$D$33 -> 50127.525 | ... M51: =M50*assumptions!$D$33 -> 50127.525 | N51: =SUM(B51:M51) -> 601530.3
A52: Software & Tools | B52: =(assumptions!$D$19*assumptions!$D$41)/12 -> 6750 | C52: =(assumptions!$D$19*assumptions!$D$41)/12 -> 6750 | D52: =(assumptions!$D$19*assumptions!$D$41)/12 -> 6750 | E52: =(assumptions!$D$19*assumptions!$D$41)/12 -> 6750 | F52: =(assumptions!$D$19*assumptions!$D$41)/12 -> 6750 | G52: =(assumptions!$D$19*assumptions!$D$41)/12 -> 6750 | H52: =(assumptions!$D$19*assumptions!$D$41)/12 -> 6750 | I52: =(assumptions!$D$19*assumptions!$D$41)/12 -> 6750 | ... M52: =(assumptions!$D$19*assumptions!$D$41)/12 -> 6750 | N52: =SUM(B52:M52) -> 81000
...

Sheet 2024_actual
A1: 2024 Actual Revenue | B1: Jan | C1: Feb | D1: Mar | E1: Apr | F1: May | G1: Jun | H1: Jul | I1: Aug | J1: Sep | K1: Oct | L1: Nov | M1: Dec | N1: FY 2024
A2: Subscription Revenue | B2: 2420000 | C2: 2440000 | D2: 2720000 | E2: 2760000 | F2: 2790000 | G2: 2820000 | H2: 2840000 | I2: 2870000 | J2: 3180000 | K2: 3220000 | L2: 3270000 | M2: 3670000 | N2: =SUM(B2:M2) -> 35000000
A3: Professional Services Revenue | B3: 270000 | C3: 275000 | D3: 305000 | E3: 310000 | F3: 315000 | G3: 315000 | H3: 320000 | I3: 325000 | J3: 360000 | K3: 365000 | L3: 375000 | M3: 465000 | N3: =SUM(B3:M3) -> 4000000
A4: Total Revenue | B4: =SUM(B2:B3) -> 2690000 | C4: =SUM(C2:C3) -> 2715000 | D4: =SUM(D2:D3) -> 3025000 | E4: =SUM(E2:E3) -> 3070000 | F4: =SUM(F2:F3) -> 3105000 | G4: =SUM(G2:G3) -> 3135000 | H4: =SUM(H2:H3) -> 3160000 | I4: =SUM(I2:I3) -> 3195000 | ... M4: =SUM(M2:M3) -> 4135000 | N4: =SUM(B4:M4) -> 39000000
A7: 2024 Actual Sales | B7: Jan | C7: Feb | D7: Mar | E7: Apr | F7: May | G7: Jun | H7: Jul | I7: Aug | J7: Sep | K7: Oct | L7: Nov | M7: Dec | N7: FY 2024
A8: Salaries & Wages | B8: 400000 | C8: 400000 | D8: 405000 | E8: 405000 | F8: 405000 | G8: 410000 | H8: 410000 | I8: 410000 | J8: 415000 | K8: 415000 | L8: 415000 | M8: 420000 | N8: =SUM(B8:M8) -> 4910000
A9: Employee Benefits | B9: 80000 | C9: 80000 | D9: 81000 | E9: 81000 | F9: 81000 | G9: 82000 | H9: 82000 | I9: 82000 | J9: 83000 | K9: 83000 | L9: 83000 | M9: 84000 | N9: =SUM(B9:M9) -> 982000
A10: Sales Commissions | B10: 121000 | C10: 122000 | D10: 136000 | E10: 138000 | F10: 139500 | G10: 141000 | H10: 142000 | I10: 143500 | J10: 159000 | K10: 161000 | L10: 163500 | M10: 183500 | N10: =SUM(B10:M10) -> 1750000
A11: Software & Tools | B11: 12000 | C11: 12000 | D11: 12000 | E11: 12000 | F11: 12000 | G11: 12000 | H11: 12000 | I11: 12000 | J11: 12000 | K11: 12000 | L11: 12000 | M11: 12000 | N11: =SUM(B11:M11) -> 144000
A12: Travel & Entertainment | B12: 14000 | C12: 15000 | D12: 15000 | E12: 16000 | F12: 16000 | G12: 17000 | H12: 17000 | I12: 17000 | J12: 18000 | K12: 18000 | L12: 19000 | M12: 19000 | N12: =SUM(B12:M12) -> 201000
A13: Total Sales Expenses | B13: =SUM(B8:B12) -> 627000 | C13: =SUM(C8:C12) -> 629000 | D13: =SUM(D8:D12) -> 649000 | E13: =SUM(E8:E12) -> 652000 | F13: =SUM(F8:F12) -> 653500 | G13: =SUM(G8:G12) -> 662000 | H13: =SUM(H8:H12) -> 663000 | I13: =SUM(I8:I12) -> 664500 | ... M13: =SUM(M8:M12) -> 718500 | N13: =SUM(B13:M13) -> 7987000
A16: 2024 Actual Marketing | B16: Jan | C16: Feb | D16: Mar | E16: Apr | F16: May | G16: Jun | H16: Jul | I16: Aug | J16: Sep | K16: Oct | L16: Nov | M16: Dec | N16: FY 2024
A17: Salaries & Wages | B17: 156000 | C17: 156000 | D17: 157000 | E17: 157000 | F17: 158000 | G17: 158000 | H17: 159000 | I17: 159000 | J17: 160000 | K17: 160000 | L17: 161000 | M17: 161000 | N17: =SUM(B17:M17) -> 1902000
A18: Employee Benefits | B18: 31200 | C18: 31200 | D18: 31400 | E18: 31400 | F18: 31600 | G18: 31600 | H18: 31800 | I18: 31800 | J18: 32000 | K18: 32000 | L18: 32200 | M18: 32200 | N18: =SUM(B18:M18) -> 380400
A19: Marketing & Advertising | B19: 180000 | C19: 185000 | D19: 195000 | E19: 200000 | F19: 205000 | G19: 210000 | H19: 215000 | I19: 220000 | J19: 230000 | K19: 235000 | L19: 240000 | M19: 265000 | N19: =SUM(B19:M19) -> 2580000
A20: Software & Tools | B20: 5000 | C20: 5000 | D20: 5000 | E20: 5000 | F20: 5000 | G20: 5000 | H20: 5000 | I20: 5000 | J20: 5000 | K20: 5000 | L20: 5000 | M20: 5000 | N20: =SUM(B20:M20) -> 60000
A21: Travel & Entertainment | B21: 3000 | C21: 3000 | D21: 3500 | E21: 3500 | F21: 4000 | G21: 4000 | H21: 4000 | I21: 4500 | J21: 4500 | K21: 5000 | L21: 5000 | M21: 6000 | N21: =SUM(B21:M21) -> 50000
A22: Total Marketing Expenses | B22: =SUM(B17:B21) -> 375200 | C22: =SUM(C17:C21) -> 380200 | D22: =SUM(D17:D21) -> 391900 | E22: =SUM(E17:E21) -> 396900 | F22: =SUM(F17:F21) -> 403600 | G22: =SUM(G17:G21) -> 408600 | H22: =SUM(H17:H21) -> 414800 | I22: =SUM(I17:I21) -> 420300 | ... M22: =SUM(M17:M21) -> 469200 | N22: =SUM(B22:M22) -> 4972400
A25: 2024 Actual Engineering | B25: Jan | C25: Feb | D25: Mar | E25: Apr | F25: May | G25: Jun | H25: Jul | I25: Aug | J25: Sep | K25: Oct | L25: Nov | M25: Dec | N25: FY 2024
A26: Salaries & Wages | B26: 775000 | C26: 775000 | D26: 780000 | E26: 780000 | F26: 785000 | G26: 785000 | H26: 790000 | I26: 790000 | J26: 795000 | K26: 795000 | L26: 800000 | M26: 800000 | N26: =SUM(B26:M26) -> 9450000
A27: Employee Benefits | B27: 155000 | C27: 155000 | D27: 156000 | E27: 156000 | F27: 157000 | G27: 157000 | H27: 158000 | I27: 158000 | J27: 159000 | K27: 159000 | L27: 160000 | M27: 160000 | N27: =SUM(B27:M27) -> 1890000
A28: Cloud & Hosting | B28: 125000 | C28: 130000 | D28: 135000 | E28: 138000 | F28: 140000 | G28: 142000 | H28: 145000 | I28: 148000 | J28: 155000 | K28: 160000 | L28: 165000 | M28: 177000 | N28: =SUM(B28:M28) -> 1760000
A29: Software & Tools | B29: 17000 | C29: 17000 | D29: 17000 | E29: 17000 | F29: 17000 | G29: 17000 | H29: 17000 | I29: 17000 | J29: 17000 | K29: 17000 | L29: 17000 | M29: 17000 | N29: =SUM(B29:M29) -> 204000
